Workbook

Sheet DR
A1: Name | B1: Nina HOLT | D1: Nina HOLT | H1: Danny WIEK | I1: Jan MALLKOWSKI | T1: Leo Ilias BAUMANN | X1: Leo Ilias BAUMANN | Y1: Leo Ilias BAUMANN | AO1: Anton KIRSCH
A2: Competiton | B2: DEM - 2025 | D2: World Games - 2025 | I2: DEM - 2018 | T2: DP - 2024 | X2: DP - 2025 | Y2: EYLC - 2024 | AO2: DMM - 2025
A3: OG | T3: Völklingen | X3: Völklingen | Y3: Völklingen | AO3: Verl
A4: WR-Open | B4: 50m Retten - offen - W | C4: 100m Retten - offen - W | D4: 100m Kombi - offen - W | E4: 100m Lifesaver - offen - W | F4: 200m Superlifesaver - offen - W | G4: 200m Hindernis - offen - W | H4: 50m Retten - offen - M | I4: 100m Retten - offen - M | J4: 100m Kombi - offen - M | K4: 100m Lifesaver - offen - M | L4: 200m Superlifesaver - offen - M | M4: 200m Hindernis - offen - M | N4: 50m Retten - 17/18 - W | O4: 100m Retten - 17/18 - W | P4: 100m Kombi -17/18 - W | Q4: 100m Lifesaver - 17/18 - W | R4: 200m Superlifesaver - 17/18 - W | S4: 200m Hindernis - 17/18 - W | T4: 50m Retten - 17/18 - M | U4: 100m Retten - 17/18 - M | V4: 100m Kombi - 17/18 - M | W4: 100m Lifesaver - 17/18 - M | X4: 200m Superlifesaver - 17/18 - M | Y4: 200m Hindernis - 17/18 - M | Z4: 50m Retten - 15/16 - W | AA4: 100m Retten - 15/16 - W | AB4: 100m Kombi - 15/16 - W | AC4: 100m Lifesaver - 15/16 - W | AD4: 200m Superlifesaver - 15/16 - W | AE4: 200m Hindernis - 15/16 - W | AF4: 50m Retten - 15/16 - M | AG4: 100m Retten - 15/16 - M | AH4: 100m Kombi -15/16 - M | AI4: 100m Lifesaver - 15/16 - M | AJ4: 200m Superlifesaver - 15/16 - M | AK4: 200m Hindernis - 15/16 - M | AL4: 50m Retten - 13/14 - W | AM4: 50m Retten mit Flossen - 13/14 - W | AN4: 100m Hindernis - 13/14 - W | AO4: 50m Retten - 13/14 - M | AP4: 50m Retten mit Flossen - 13/14 - M | AQ4: 100m Hindernis - 13/14 - M | AR4: 50m Flossen - 12 - W | AS4: 50m komb. Schwimmen - 12 - W | AT4: 50m Hindernis - 12 - W | AU4: 50m Flossen - 12 - M | AV4: 50m komb. Schwimmen - 12 - M | AW4: 50m Hindernis - 12 - M
A5: 2000
A6: =A5+1 -> 2001 | B6: 0.00045 | C6: 0.00070497685 | D6: 0.00091134259 | E6: 0.00073368056 | F6: 0.001794213 | G6: 0.0015353009 | H6: 0.00037476852 | I6: 0.00060335648 | J6: 0.00076516204 | K6: 0.000646875 | L6: 0.0015703704 | M6: 0.001362963
A7: =A6+1 -> 2002 | B7: 0.00045 | C7: 0.00070497685 | D7: 0.00091134259 | E7: 0.00073368056 | F7: 0.001794213 | G7: 0.0015353009 | H7: 0.00037476852 | I7: 0.00060335648 | J7: 0.00076516204 | K7: 0.000646875 | L7: 0.0015703704 | M7: 0.001362963
A8: =A7+1 -> 2003 | B8: 0.0004150463 | C8: 0.00068645833 | D8: 0.00086585648 | E8: 0.00073368056 | F8: 0.0017447917 | G8: 0.0015210648 | H8: 0.00035949074 | I8: 0.00060277778 | J8: 0.00073287037 | K8: 0.00063622685 | L8: 0.0015243056 | M8: 0.0013346065
A9: =A8+1 -> 2004 | B9: 0.00041446759 | C9: 0.00065891204 | D9: 0.00086585648 | E9: 0.00072858796 | F9: 0.0017341435 | G9: 0.0015210648 | H9: 0.00035532407 | I9: 0.00058472222 | J9: 0.00073287037 | K9: 0.00063460648 | L9: 0.001503125 | M9: 0.0013346065
A10: =A9+1 -> 2005 | B10: 0.0004130787 | C10: 0.00065891204 | D10: 0.00085243056 | E10: 0.00071979167 | F10: 0.0017252315 | G10: 0.0015210648 | H10: 0.00035532407 | I10: 0.00058472222 | J10: 0.00072893519 | K10: 0.00062210648 | L10: 0.001496412 | M10: 0.0013346065
A11: =A10+1 -> 2006 | B11: 0.00041203704 | C11: 0.00065891204 | D11: 0.00085243056 | E11: 0.00071979167 | F11: 0.0017252315 | G11: 0.0015210648 | H11: 0.00035532407 | I11: 0.00058425926 | J11: 0.00071458333 | K11: 0.00062210648 | L11: 0.001496412 | M11: 0.0013346065
A12: =A11+1 -> 2007 | B12: 0.00040810185 | C12: 0.00065891204 | D12: 0.00084236111 | E12: 0.00071979167 | F12: 0.0017197917 | G12: 0.0015043981 | H12: 0.00035520833 | I12: 0.00058425926 | J12: 0.00073657407 | K12: 0.00062210648 | L12: 0.001496412 | M12: 0.0013346065 | N12: 0.0004525463 | O12: 0.00071296296 | S12: 0.0016435185 | T12: 0.00038541667 | U12: 0.000625 | Y12: 0.0015011574 | Z12: 0.0004837963 | AA12: 0.00074884259 | AF12: 0.00040972222 | AG12: 0.00067013889 | AL12: 0.00048263889 | AM12: 0.00035185185 | AN12: 0.0007662037 | AO12: 0.00041550926 | AP12: 0.00031134259 | AQ12: 0.00068518519 | AR12: 0.00028125 | AS12: 0.00041319444 | AT12: 0.00036921296 | AU12: 0.00027314815 | AV12: 0.00040625 | AW12: 0.0003599537
A13: =A12+1 -> 2008 | B13: 0.00040810185 | C13: 0.00065891204 | D13: 0.00084236111 | E13: 0.00071712963 | F13: 0.0017197917 | G13: 0.0015037037 | H13: 0.0003412037 | I13: 0.00057280093 | J13: 0.00072615741 | K13: 0.00062210648 | L13: 0.001496412 | M13: 0.0013346065 | N13: 0.00045069444 | O13: 0.00071296296 | S13: 0.0015952546 | T13: 0.00038541667 | U13: 0.00062349537 | Y13: 0.0014349537 | Z13: 0.00045069444 | AA13: 0.00074884259 | AF13: 0.00040659722 | AG13: 0.00065671296 | AL13: 0.00048263889 | AM13: 0.00035185185 | AN13: 0.00081539352 | AO13: 0.00041550926 | AP13: 0.00031134259 | AQ13: 0.00074803241 | AR13: 0.00028125 | AS13: 0.000409375 | AT13: 0.00036921296 | AU13: 0.00027314815 | AV13: 0.00040625 | AW13: 0.0003599537
A14: =A13+1 -> 2009 | B14: 0.00040810185 | C14: 0.00065891204 | D14: 0.00084236111 | E14: 0.00070150463 | F14: 0.0017197917 | G14: 0.0014934028 | H14: 0.0003412037 | I14: 0.00057199074 | J14: 0.00071435185 | K14: 0.00062210648 | L14: 0.001496412 | M14: 0.0013346065 | N14: 0.00044965278 | O14: 0.00071296296 | S14: 0.0015733796 | T14: 0.00038530093 | U14: 0.00061851852 | Y14: 0.0014349537 | Z14: 0.00044965278 | AA14: 0.00074363426 | AF14: 0.00040659722 | AG14: 0.00065393519 | AL14: 0.00048263889 | AM14: 0.00035185185 | AN14: 0.00081539352 | AO14: 0.00041550926 | AP14: 0.00031134259 | AQ14: 0.00074803241 | AR14: 0.00027349537 | AS14: 0.000409375 | AT14: 0.00036921296 | AU14: 0.00025069444 | AV14: 0.00040625 | AW14: 0.0003599537
A15: =A14+1 -> 2010 | B15: 0.00040810185 | C15: 0.00065289352 | D15: 0.00084236111 | E15: 0.00070150463 | F15: 0.0017197917 | G15: 0.0014106481 | H15: 0.0003349537 | I15: 0.00055972222 | J15: 0.00069189815 | K15: 0.00062210648 | L15: 0.001496412 | M15: 0.0013306713 | N15: 0.00043553241 | O15: 0.00071296296 | S15: 0.0015733796 | T15: 0.0003712963 | U15: 0.00061851852 | Y15: 0.0014349537 | Z15: 0.00044965278 | AA15: 0.00074363426 | AF15: 0.00040659722 | AG15: 0.00065393519 | AL15: 0.00048263889 | AM15: 0.00034791667 | AN15: 0.00081539352 | AO15: 0.00041550926 | AP15: 0.00031099537 | AQ15: 0.00071458333 | AR15: 0.00027349537 | AS15: 0.000409375 | AT15: 0.00036921296 | AU15: 0.00025069444 | AV15: 0.00040625 | AW15: 0.0003599537
A16: =A15+1 -> 2011 | B16: 0.00040810185 | C16: 0.00065289352 | D16: 0.00084178241 | E16: 0.00070150463 | F16: 0.0017197917 | G16: 0.0014106481 | H16: 0.0003349537 | I16: 0.00055972222 | J16: 0.00069189815 | K16: 0.00062210648 | L16: 0.001496412 | M16: 0.0013306713 | N16: 0.00040810185 | O16: 0.00065289352 | P16: 0.00084178241 | Q16: 0.00070150463 | R16: 0.0017197917 | S16: 0.0014106481 | T16: 0.0003349537 | U16: 0.00055972222 | V16: 0.00069189815 | W16: 0.00062210648 | X16: 0.001496412 | Y16: 0.0013306713 | Z16: 0.00044965278 | AA16: 0.00074363426 | AF16: 0.00038599537 | AG16: 0.00064583333 | AL16: 0.00048263889 | AM16: 0.00034618056 | AN16: 0.00081539352 | AO16: 0.00041550926 | AP16: 0.00030451389 | AQ16: 0.00071458333 | AR16: 0.00027349537 | AS16: 0.000409375 | AT16: 0.00036921296 | AU16: 0.00025069444 | AV16: 0.00040625 | AW16: 0.00035324074
A17: =A16+1 -> 2012 | B17: 0.00040810185 | C17: 0.0006525463 | D17: 0.00084027778 | E17: 0.00070011574 | F17: 0.0016951389 | G17: 0.0014106481 | H17: 0.0003349537 | I17: 0.00055416667 | J17: 0.00069189815 | K17: 0.00061273148 | L17: 0.0014798611 | M17: 0.0013306713 | N17: 0.00040810185 | O17: 0.0006525463 | P17: 0.00084027778 | Q17: 0.00070011574 | R17: 0.0016951389 | S17: 0.0014106481 | T17: 0.0003349537 | U17: 0.00055416667 | V17: 0.00069189815 | W17: 0.00061273148 | X17: 0.0014798611 | Y17: 0.0013306713 | Z17: 0.00044965278 | AA17: 0.00073738426 | AF17: 0.00038599537 | AG17: 0.00062997685 | AL17: 0.00048263889 | AM17: 0.00034618056 | AN17: 0.00081539352 | AO17: 0.00041550926 | AP17: 0.00030451389 | AQ17: 0.00071458333 | AR17: 0.00027349537 | AS17: 0.000409375 | AT17: 0.00036921296 | AU17: 0.00025069444 | AV17: 0.00040625 | AW17: 0.00035324074
A18: =A17+1 -> 2013 | B18: 0.00040810185 | C18: 0.0006525463 | D18: 0.0008244213 | E18: 0.00070011574 | F18: 0.0016730324 | G18: 0.0014106481 | H18: 0.0003349537 | I18: 0.0005375 | J18: 0.00069189815 | K18: 0.00059444444 | L18: 0.0014798611 | M18: 0.001312963 | N18: 0.00040810185 | O18: 0.0006525463 | P18: 0.0008244213 | Q18: 0.00070011574 | R18: 0.0016730324 | S18: 0.0014106481 | T18: 0.0003349537 | U18: 0.0005375 | V18: 0.00069189815 | W18: 0.00059444444 | X18: 0.0014798611 | Y18: 0.001312963 | Z18: 0.00044965278 | AA18: 0.00073738426 | AF18: 0.00037962963 | AG18: 0.00062997685 | AL18: 0.00048263889 | AM18: 0.00034618056 | AN18: 0.00081539352 | AO18: 0.00041550926 | AP18: 0.00030451389 | AQ18: 0.00071458333 | AR18: 0.00027349537 | AS18: 0.000409375 | AT18: 0.00036921296 | AU18: 0.00025069444 | AV18: 0.00040625 | AW18: 0.00035324074
A19: =A18+1 -> 2014 | B19: 0.00040208333 | C19: 0.00064490741 | D19: 0.00080543981 | E19: 0.00069074074 | F19: 0.0016730324 | G19: 0.0014106481 | H19: 0.0003349537 | I19: 0.00053229167 | J19: 0.00069189815 | K19: 0.00058483796 | L19: 0.0014621528 | M19: 0.001312963 | N19: 0.00040208333 | O19: 0.00064490741 | P19: 0.00080543981 | Q19: 0.00069074074 | R19: 0.0016730324 | S19: 0.0014106481 | T19: 0.0003349537 | U19: 0.00053229167 | V19: 0.00069189815 | W19: 0.00058483796 | X19: 0.0014621528 | Y19: 0.001312963 | Z19: 0.000440625 | AA19: 0.00073472222 | AF19: 0.00037962963 | AG19: 0.00062997685 | AL19: 0.00048263889 | AM19: 0.00034618056 | AN19: 0.00080983796 | AO19: 0.00041550926 | AP19: 0.00030451389 | AQ19: 0.00071458333 | AR19: 0.00027349537 | AS19: 0.000409375 | AT19: 0.00036921296 | AU19: 0.00025069444 | AV19: 0.00040393519 | AW19: 0.00035324074
A20: =A19+1 -> 2015 | B20: 0.00040208333 | C20: 0.00059768519 | D20: 0.00080069444 | E20: 0.00067164352 | F20: 0.0016690972 | G20: 0.0014106481 | H20: 0.00032696759 | I20: 0.00052256944 | J20: 0.00069189815 | K20: 0.00058287037 | L20: 0.0014543981 | M20: 0.0013116898 | N20: 0.00040208333 | O20: 0.00059768519 | P20: 0.00080069444 | Q20: 0.00067164352 | R20: 0.0016690972 | S20: 0.0014106481 | T20: 0.00032696759 | U20: 0.00052256944 | V20: 0.00069189815 | W20: 0.00058287037 | X20: 0.0014543981 | Y20: 0.0013116898 | Z20: 0.000440625 | AA20: 0.00072534722 | AF20: 0.00037962963 | AG20: 0.00059293981 | AL20: 0.00048263889 | AM20: 0.00034618056 | AN20: 0.00080983796 | AO20: 0.00041550926 | AP20: 0.00030451389 | AQ20: 0.00071458333 | AR20: 0.00026273148 | AS20: 0.00039652778 | AT20: 0.00036921296 | AU20: 0.00025069444 | AV20: 0.00040393519 | AW20: 0.00035324074
A21: =A20+1 -> 2016 | B21: 0.00039664352 | C21: 0.00059768519 | D21: 0.00080069444 | E21: 0.00067164352 | F21: 0.0016690972 | G21: 0.0014106481 | H21: 0.00032696759 | I21: 0.00052256944 | J21: 0.00069189815 | K21: 0.00058287037 | L21: 0.0014543981 | M21: 0.0013116898 | N21: 0.00039664352 | O21: 0.00059768519 | P21: 0.00080069444 | Q21: 0.00067164352 | R21: 0.0016690972 | S21: 0.0014106481 | T21: 0.00032696759 | U21: 0.00052256944 | V21: 0.00069189815 | W21: 0.00058287037 | X21: 0.0014543981 | Y21: 0.0013116898 | Z21: 0.000440625 | AA21: 0.00069236111 | AF21: 0.00037962963 | AG21: 0.00057118056 | AL21: 0.0004650463 | AM21: 0.00033877315 | AN21: 0.00079398148 | AO21: 0.00041550926 | AP21: 0.0003025463 | AQ21: 0.00071458333 | AR21: 0.00026273148 | AS21: 0.00037835648 | AT21: 0.00035914352 | AU21: 0.00025069444 | AV21: 0.00039525463 | AW21: 0.00035324074
A22: =A21+1 -> 2017 | B22: 0.00037951389 | C22: 0.00059768519 | D22: 0.00079699074 | E22: 0.00067060185 | F22: 0.0016438657 | G22: 0.0014106481 | H22: 0.00032476852 | I22: 0.00052256944 | J22: 0.00068726852 | K22: 0.00057719907 | L22: 0.0014452546 | M22: 0.0013116898 | N22: 0.00037951389 | O22: 0.00059768519 | P22: 0.00079699074 | Q22: 0.00067060185 | R22: 0.0016438657 | S22: 0.0014106481 | T22: 0.00032476852 | U22: 0.00052256944 | V22: 0.00068726852 | W22: 0.00057719907 | X22: 0.0014452546 | Y22: 0.0013116898 | Z22: 0.000440625 | AA22: 0.00069236111 | AF22: 0.00037962963 | AG22: 0.00057118056 | AL22: 0.00046342593 | AM22: 0.00031840278 | AN22: 0.00076979167 | AO22: 0.00041550926 | AP22: 0.00029907407 | AQ22: 0.00070868056 | AR22: 0.00026273148 | AS22: 0.00037835648 | AT22: 0.00035914352 | AU22: 0.00024675926 | AV22: 0.00039525463 | AW22: 0.0003474537
A23: =A22+1 -> 2018 | B23: 0.00037951389 | C23: 0.00059768519 | D23: 0.00079699074 | E23: 0.00066180556 | F23: 0.0016403935 | G23: 0.0014106481 | H23: 0.000315625 | I23: 0.000521875 | J23: 0.00068078704 | K23: 0.00056736111 | L23: 0.0014390046 | M23: 0.0013116898 | N23: 0.00037951389 | O23: 0.00059768519 | P23: 0.00079699074 | Q23: 0.00066180556 | R23: 0.0016403935 | S23: 0.0014106481 | T23: 0.000315625 | U23: 0.000521875 | V23: 0.00068078704 | W23: 0.00056736111 | X23: 0.0014390046 | Y23: 0.0013116898 | Z23: 0.000440625 | AA23: 0.00068993056 | AF23: 0.00037962963 | AG23: 0.00057118056 | AL23: 0.00045081019 | AM23: 0.00031018519 | AN23: 0.00074722222 | AO23: 0.00041550926 | AP23: 0.00029212963 | AQ23: 0.00070868056 | AR23: 0.00026273148 | AS23: 0.00037835648 | AT23: 0.00035914352 | AU23: 0.00024675926 | AV23: 0.00039525463 | AW23: 0.0003474537
A24: =A23+1 -> 2019 | B24: 0.00037951389 | C24: 0.00058773148 | D24: 0.00079699074 | E24: 0.00066030093 | F24: 0.0016403935 | G24: 0.0014106481 | H24: 0.000315625 | I24: 0.00051168981 | J24: 0.00068078704 | K24: 0.00056736111 | L24: 0.0014390046 | M24: 0.0013116898 | N24: 0.00037951389 | O24: 0.00058773148 | P24: 0.00079699074 | Q24: 0.00066030093 | R24: 0.0016403935 | S24: 0.0014106481 | T24: 0.000315625 | U24: 0.00051168981 | V24: 0.00068078704 | W24: 0.00056736111 | X24: 0.0014390046 | Y24: 0.0013116898 | Z24: 0.00042777778 | AA24: 0.00063668981 | AF24: 0.00037962963 | AG24: 0.00057118056 | AL24: 0.00045081019 | AM24: 0.00031018519 | AN24: 0.00074722222 | AO24: 0.00041550926 | AP24: 0.00026886574 | AQ24: 0.00070868056 | AR24: 0.00026273148 | AS24: 0.00037835648 | AT24: 0.00035914352 | AU24: 0.00024675926 | AV24: 0.00039525463 | AW24: 0.0003474537
A25: =A24+1 -> 2020 | B25: 0.00039675926 | C25: 0.00060358796 | D25: 0.00082673611 | E25: 0.00066643519 | F25: 0.0016587963 | G25: 0.0015241898 | H25: 0.000315625 | I25: 0.00050972222 | J25: 0.00068356481 | K25: 0.00057152778 | L25: 0.0014543981 | M25: 0.0013541667 | N25: 0.00040798611 | O25: 0.00060358796 | P25: 0.00085196759 | Q25: 0.00070520833 | R25: 0.001740625 | S25: 0.0015274306 | T25: 0.00034907407 | U25: 0.00053194444 | V25: 0.00072303241 | W25: 0.00060405093 | X25: 0.001544213 | Y25: 0.0014155093 | Z25: 0.00040798611 | AA25: 0.00060358796 | AB25: 0.00085196759 | AC25: 0.0007087963 | AD25: 0.001740625 | AE25: 0.0015274306 | AF25: 0.00037488426 | AG25: 0.00057118056 | AH25: 0.00082638889 | AI25: 0.00065324074 | AJ25: 0.0016990741 | AK25: 0.0014334491 | AL25: 0.00045081019 | AM25: 0.00031018519 | AN25: 0.00074722222 | AO25: 0.00041550926 | AP25: 0.00026886574 | AQ25: 0.00070868056 | AR25: 0.00026273148 | AS25: 0.00037835648 | AT25: 0.00035914352 | AU25: 0.00024675926 | AV25: 0.00039525463 | AW25: 0.0003474537
A26: =A25+1 -> 2021 | B26: 0.00039675926 | C26: 0.00060358796 | D26: 0.00082673611 | E26: 0.00066643519 | F26: 0.001687963 | G26: 0.0015241898 | H26: 0.000315625 | I26: 0.00050972222 | J26: 0.00068356481 | K26: 0.00057152778 | L26: 0.0014543981 | M26: 0.0013541667 | N26: 0.00040798611 | O26: 0.00060358796 | P26: 0.00085196759 | Q26: 0.00070520833 | R26: 0.001740625 | S26: 0.0015274306 | T26: 0.00034907407 | U26: 0.00053194444 | V26: 0.00072303241 | W26: 0.00060405093 | X26: 0.001544213 | Y26: 0.0014155093 | Z26: 0.00040798611 | AA26: 0.00060358796 | AB26: 0.00085196759 | AC26: 0.0007087963 | AD26: 0.001740625 | AE26: 0.0015274306 | AF26: 0.00037488426 | AG26: 0.00057118056 | AH26: 0.00082638889 | AI26: 0.00065324074 | AJ26: 0.0016990741 | AK26: 0.0014334491 | AL26: 0.00045081019 | AM26: 0.00031018519 | AN26: 0.00074722222 | AO26: 0.00041550926 | AP26: 0.00026886574 | AQ26: 0.00070868056 | AR26: 0.00026273148 | AS26: 0.00037835648 | AT26: 0.00035914352 | AU26: 0.00024675926 | AV26: 0.00039525463 | AW26: 0.0003474537
A27: =A26+1 -> 2022 | B27: 0.00039398148 | C27: 0.00060358796 | D27: 0.00081666667 | E27: 0.00066643519 | F27: 0.001687963 | G27: 0.0015050926 | H27: 0.000315625 | I27: 0.00050972222 | J27: 0.00068356481 | K27: 0.00057152778 | L27: 0.0014543981 | M27: 0.0013541667 | N27: 0.00039398148 | O27: 0.00060358796 | P27: 0.00081666667 | Q27: 0.00070520833 | R27: 0.001690625 | S27: 0.0015050926 | T27: 0.00034907407 | U27: 0.00053194444 | V27: 0.00072303241 | W27: 0.00060405093 | X27: 0.001544213 | Y27: 0.0014155093 | Z27: 0.00040798611 | AA27: 0.00060358796 | AB27: 0.00085196759 | AC27: 0.0007087963 | AD27: 0.001740625 | AE27: 0.0015274306 | AF27: 0.00037488426 | AG27: 0.00057118056 | AH27: 0.00082638889 | AI27: 0.00065324074 | AJ27: 0.0016990741 | AK27: 0.0014334491 | AL27: 0.00045046296 | AM27: 0.00031018519 | AN27: 0.00074722222 | AO27: 0.00041550926 | AP27: 0.00026886574 | AQ27: 0.00070868056 | AR27: 0.00026273148 | AS27: 0.00037835648 | AT27: 0.00035914352 | AU27: 0.00024675926 | AV27: 0.00039525463 | AW27: 0.0003474537
A28: =A27+1 -> 2023 | B28: 0.00037974537 | C28: 0.00058599537 | D28: 0.00077592593 | E28: 0.00064930556 | F28: 0.0016552083 | G28: 0.0014525463 | H28: 0.000315625 | I28: 0.00050972222 | J28: 0.00068356481 | K28: 0.00057152778 | L28: 0.0014543981 | M28: 0.0013541667 | N28: 0.00039398148 | O28: 0.00060358796 | P28: 0.00081666667 | Q28: 0.00070520833 | R28: 0.001690625 | S28: 0.0015050926 | T28: 0.00034907407 | U28: 0.00053194444 | V28: 0.00072303241 | W28: 0.00060405093 | X28: 0.001544213 | Y28: 0.0014155093 | Z28: 0.00040798611 | AA28: 0.00060358796 | AB28: 0.00085196759 | AC28: 0.0007087963 | AD28: 0.001740625 | AE28: 0.0015274306 | AF28: 0.00037488426 | AG28: 0.00057118056 | AH28: 0.00080173611 | AI28: 0.00065324074 | AJ28: 0.0016990741 | AK28: 0.0014334491 | AL28: 0.00045046296 | AM28: 0.00031018519 | AN28: 0.00074722222 | AO28: 0.00041550926 | AP28: 0.00026886574 | AQ28: 0.00070868056 | AR28: 0.00026273148 | AS28: 0.00037835648 | AT28: 0.00035914352 | AU28: 0.00024675926 | AV28: 0.00039525463 | AW28: 0.0003474537
A29: =A28+1 -> 2024 | B29: 0.00037835648 | C29: 0.00058599537 | D29: 0.0007693287 | E29: 0.00064930556 | F29: 0.0016347222 | G29: 0.0014525463 | H29: 0.000315625 | I29: 0.00050972222 | J29: 0.00068356481 | K29: 0.00057152778 | L29: 0.0014543981 | M29: 0.0013541667 | N29: 0.0003869213 | O29: 0.00060358796 | P29: 0.00081539352 | Q29: 0.00067349537 | R29: 0.001690625 | S29: 0.0015050926 | T29: 0.00034907407 | U29: 0.00053194444 | V29: 0.00072303241 | W29: 0.00060405093 | X29: 0.0015293981 | Y29: 0.0013997685 | Z29: 0.00040798611 | AA29: 0.00060358796 | AB29: 0.00085196759 | AC29: 0.0007087963 | AD29: 0.001740625 | AE29: 0.0015274306 | AF29: 0.00036064815 | AG29: 0.00056747685 | AH29: 0.00075671296 | AI29: 0.00064710648 | AJ29: 0.001625463 | AK29: 0.0014334491 | AL29: 0.00045046296 | AM29: 0.00031018519 | AN29: 0.00074722222 | AO29: 0.00039733796 | AP29: 0.00026886574 | AQ29: 0.00069618056 | AR29: 0.00026273148 | AS29: 0.00037835648 | AT29: 0.00035914352 | AU29: 0.00024675926 | AV29: 0.00037349537 | AW29: 0.0003474537
A30: =A29+1 -> 2025 | B30: 0.00037268519 | C30: 0.00058599537 | D30: 0.00076099537 | E30: 0.00064606481 | F30: 0.0016347222 | G30: 0.0014387731 | H30: 0.000315625 | I30: 0.00050972222 | J30: 0.00068356481 | K30: 0.00057152778 | L30: 0.0014543981 | M30: 0.0013541667 | N30: 0.0003869213 | O30: 0.00060358796 | P30: 0.00081539352 | Q30: 0.00067349537 | R30: 0.001690625 | S30: 0.0015050926 | T30: 0.00033518519 | U30: 0.00053194444 | V30: 0.00072303241 | W30: 0.00060405093 | X30: 0.0015293981 | Y30: 0.0013666667 | Z30: 0.00040798611 | AA30: 0.00060358796 | AB30: 0.00085196759 | AC30: 0.0007087963 | AD30: 0.001740625 | AE30: 0.0015274306 | AF30: 0.00033518519 | AG30: 0.00056747685 | AH30: 0.00073993056 | AI30: 0.00064710648 | AJ30: 0.001591088 | AK30: 0.0013666667 | AL30: 0.00045046296 | AM30: 0.00031018519 | AN30: 0.00074722222 | AO30: 0.00039733796 | AP30: 0.00026886574 | AQ30: 0.00069618056 | AR30: 0.00026273148 | AS30: 0.00037835648 | AT30: 0.00035914352 | AU30: 0.00024675926 | AV30: 0.00037349537 | AW30: 0.0003474537
A31: =A30+1 -> 2026 | B31: 0.00036435185 | C31: 0.00058599537 | D31: 0.00073715278 | E31: 0.00064606481 | F31: 0.0016347222 | G31: 0.0014387731 | H31: 0.000315625 | I31: 0.00050972222 | J31: 0.00068356481 | K31: 0.00057152778 | L31: 0.0014543981 | M31: 0.0013541667 | N31: 0.0003869213 | O31: 0.00060358796 | P31: 0.00081539352 | Q31: 0.00067349537 | R31: 0.001690625 | S31: 0.0015050926 | T31: 0.00033518519 | U31: 0.00053194444 | V31: 0.00072303241 | W31: 0.00060405093 | X31: 0.0014880787 | Y31: 0.0013666667 | Z31: 0.00040798611 | AA31: 0.00060358796 | AB31: 0.00085196759 | AC31: 0.0007087963 | AD31: 0.001740625 | AE31: 0.0015274306 | AF31: 0.00033518519 | AG31: 0.00056747685 | AH31: 0.00073993056 | AI31: 0.00064710648 | AJ31: 0.001591088 | AK31: 0.0013666667 | AL31: 0.00045046296 | AM31: 0.00031018519 | AN31: 0.00074722222 | AO31: 0.000390625 | AP31: 0.00026886574 | AQ31: 0.00069618056 | AR31: 0.00026273148 | AS31: 0.00037835648 | AT31: 0.00035914352 | AU31: 0.00024675926 | AV31: 0.00037349537 | AW31: 0.0003474537

Sheet WR-Youth
A1: Name | B1: Zoe PEDERSEN | C1: Lucreza FABRETTI | D1: Zoe PEDERSEN | E1: Melissa GIORDANO | F1: Bianca RAYWARD | G1: Giulia VETRANO | H1: Giovanni MASTRORILLI | I1: Jaime IRUESTE ROJO | J1: Simone LOCCHI | K1: Alberto TURRADO | L1: Davide CREMONINI | M1: Zac REID
A2: Competiton | B2: Aon-NZPRC - 2025 | C2: Riccione - 2019 | D2: LWC - 2024 | E2: Riccione - 2024 | F2: Battle of Tasman - 2025 | G2: Riccione - 2022 | H2: Orange Cup - 2024 | I2: Alicante - 2024 | J2: German Cup - 2022 | K2: Torrevieja - 2021 | L2: Riccione - 2022 | M2: LWC - 2018
A3: Nation | B3: NZL | C3: ITA | D3: NZL | E3: ITA | F3: AUS | G3: ITA | H3: ITA | I3: ESP | J3: ITA | K3: ESP | L3: ITA | M3: AUS
A4: WR-Youth | B4: 50m Retten | C4: 100m Retten | D4: 100m Kombi | E4: 100m Lifesaver | F4: 200m Superlifesaver | G4: 200m Hindernis | H4: 50m Retten2 | I4: 100m Retten2 | J4: 100m Kombi2 | K4: 100m Lifesaver2 | L4: 200m Superlifesaver2 | M4: 200m Hindernis2
A5: 2000
A6: =A5+1 -> 2001
A7: =A6+1 -> 2002
A8: =A7+1 -> 2003
A9: =A8+1 -> 2004
A10: =A9+1 -> 2005
A11: =A10+1 -> 2006
A12: =A11+1 -> 2007
A13: =A12+1 -> 2008
A14: =A13+1 -> 2009
A15: =A14+1 -> 2010
A16: =A15+1 -> 2011
A17: =A16+1 -> 2012
... A19: =A18+1 -> 2014
A20: =A19+1 -> 2015 | B20: 0.00043194444 | C20: 0.00065798611 | D20: 0.00084861111 | E20: 0.00070185185 | F20: 0.0017334491 | G20: 0.0014596065 | H20: 0.00036018519 | I20: 0.00055081019 | J20: 0.00073599537 | K20: 0.00062881944 | L20: 0.0015302083 | M20: 0.0013592593
A21: =A20+1 -> 2016 | B21: 0.00041574074 | C21: 0.00064398148 | D21: 0.00084861111 | E21: 0.00070185185 | F21: 0.0017334491 | G21: 0.0014596065 | H21: 0.00034456019 | I21: 0.00054108796 | J21: 0.00071898148 | K21: 0.00060405093 | L21: 0.0015302083 | M21: 0.0013592593
A22: =A21+1 -> 2017 | B22: 0.00039884259 | C22: 0.00064039352 | D22: 0.00084398148 | E22: 0.00069409722 | F22: 0.0017334491 | G22: 0.0014596065 | H22: 0.00034456019 | I22: 0.00054108796 | J22: 0.00071898148 | K22: 0.00060405093 | L22: 0.0015229167 | M22: 0.0013577546
A23: =A22+1 -> 2018 | B23: 0.00039884259 | C23: 0.00060416667 | D23: 0.00083888889 | E23: 0.00068877315 | F23: 0.0017063657 | G23: 0.0014596065 | H23: 0.00034456019 | I23: 0.00054108796 | J23: 0.00071898148 | K23: 0.00060405093 | L23: 0.0015229167 | M23: 0.0013577546
A24: =A23+1 -> 2019 | B24: 0.00039884259 | C24: 0.00058368056 | D24: 0.00081261574 | E24: 0.00068877315 | F24: 0.001665162 | G24: 0.0014596065 | H24: 0.00034456019 | I24: 0.00053310185 | J24: 0.00071898148 | K24: 0.00060405093 | L24: 0.0015229167 | M24: 0.0013511574
A25: =A24+1 -> 2020 | B25: 0.00039884259 | C25: 0.00057094907 | D25: 0.00081261574 | E25: 0.00068321759 | F25: 0.0016472222 | G25: 0.0014596065 | H25: 0.00034456019 | I25: 0.00053194444 | J25: 0.00071898148 | K25: 0.00060405093 | L25: 0.0015229167 | M25: 0.0013511574
A26: =A25+1 -> 2021 | B26: 0.00039884259 | C26: 0.00057094907 | D26: 0.00081261574 | E26: 0.00068321759 | F26: 0.0016472222 | G26: 0.0014596065 | H26: 0.00034456019 | I26: 0.00053194444 | J26: 0.00071898148 | K26: 0.00060405093 | L26: 0.0015229167 | M26: 0.0013511574
A27: =A26+1 -> 2022 | B27: 0.00039398148 | C27: 0.00057094907 | D27: 0.00081261574 | E27: 0.0006787037 | F27: 0.0016472222 | G27: 0.0014388889 | H27: 0.00034224537 | I27: 0.00053194444 | J27: 0.00070277778 | K27: 0.00057881944 | L27: 0.0015097222 | M27: 0.0013511574
A28: =A27+1 -> 2023 | B28: 0.00039398148 | C28: 0.00057094907 | D28: 0.00081261574 | E28: 0.00067719907 | F28: 0.0016472222 | G28: 0.001433912 | H28: 0.0003380787 | I28: 0.00053194444 | J28: 0.00069027778 | K28: 0.00057881944 | L28: 0.0014707176 | M28: 0.0013511574
A29: =A28+1 -> 2024 | B29: 0.0003869213 | C29: 0.00057094907 | D29: 0.00081261574 | E29: 0.00066134259 | F29: 0.0016472222 | G29: 0.001433912 | H29: 0.0003380787 | I29: 0.00053194444 | J29: 0.00069027778 | K29: 0.00057881944 | L29: 0.0014707176 | M29: 0.0013511574
A30: =A29+1 -> 2025 | B30: 0.0003869213 | C30: 0.00057094907 | D30: 0.00079976852 | E30: 0.00066076389 | F30: 0.0016472222 | G30: 0.001433912 | H30: 0.00033425926 | I30: 0.00052685185 | J30: 0.00069027778 | K30: 0.00057881944 | L30: 0.0014707176 | M30: 0.0013511574
A31: =A30+1 -> 2026 | B31: 0.00038287037 | C31: 0.00057094907 | D31: 0.00079976852 | E31: 0.00066076389 | F31: 0.001646875 | G31: 0.001433912 | H31: 0.00033425926 | I31: 0.00052685185 | J31: 0.00069027778 | K31: 0.00057881944 | L31: 0.0014707176 | M31: 0.0013511574
A32: =A31+1 -> 2027 | B32: 0.00038287037 | C32: 0.00057094907 | D32: 0.00079976852 | E32: 0.00066076389 | F32: 0.001646875 | G32: 0.001433912 | H32: 0.00033425926 | I32: 0.00052685185 | J32: 0.00069027778 | K32: 0.00057881944 | L32: 0.0014707176 | M32: 0.0013511574

Sheet WR-Open
A1: Name | B1: Nina HOLT | C1: Lucrezia FABRETTI | D1: Nina HOLT | E1: Madison KIDD | F1: Magalie ROUSSAU | G1: Ying LU | H1: Eadie FERGUS | I1: Tom DOURAGER | J1: Simone LOCCHI | K1: Harrison HYNES | L1: Francesco IPPOLITO | M1: Kacper MAJCHRZAK
A2: Competiton | B2: DEM - 2025 | C2: Milano - 2022 | D2: World Games - 2025 | E2: Aon-NZPRC - 2025 | F2: Saint Malo - 2022 | G2: Kaohsiung - 2009 | H2: LWC - 2024 | I2: French Rescue - 2025 | J2: Orange Cup - 2025 | K2: LWC - 2024 | L2: Riccione - 2023 | M2: LWC - 2024
A3: Nation | B3: GER | C3: ITA | D3: GER | E3: NZL | F3: FRA | G3: CHN | H3: NZL | I3: FRA | J3: ITA | K3: AUS | L3: ITA | M3: POL
A4: WR-Open | B4: 50m Retten | C4: 100m Retten | D4: 100m Kombi | E4: 100m Lifesaver | F4: 200m Superlifesaver | G4: 200m Hindernis | H4: 50m Retten2 | I4: 100m Retten2 | J4: 100m Kombi2 | K4: 100m Lifesaver2 | L4: 200m Superlifesaver2 | M4: 200m Hindernis2
A5: 2000
A6: =A5+1 -> 2001 | C6: 0.00070497685 | E6: 0.00073368056 | G6: 0.0015353009 | I6: 0.00060335648 | K6: 0.000646875 | M6: 0.001362963
A7: =A6+1 -> 2002 | B7: 0.00045 | C7: 0.00068645833 | D7: 0.00091134259 | E7: 0.00073368056 | F7: 0.001794213 | G7: 0.0015353009 | H7: 0.00037476852 | I7: 0.00060335648 | J7: 0.00076516204 | K7: 0.000646875 | L7: 0.0015703704 | M7: 0.001362963
A8: =A7+1 -> 2003 | B8: 0.0004150463 | C8: 0.00069363426 | D8: 0.00086585648 | E8: 0.00073368056 | F8: 0.0017427083 | G8: 0.0015210648 | H8: 0.00035949074 | I8: 0.00060335648 | J8: 0.00073287037 | K8: 0.00063622685 | L8: 0.0015243056 | M8: 0.0013346065
A9: =A8+1 -> 2004 | B9: 0.00041446759 | C9: 0.00069363426 | D9: 0.00086585648 | E9: 0.00072858796 | F9: 0.0017341435 | G9: 0.0015210648 | H9: 0.00035532407 | I9: 0.00058472222 | J9: 0.00073287037 | K9: 0.00063460648 | L9: 0.001503125 | M9: 0.0013346065
A10: =A9+1 -> 2005 | B10: 0.0004130787 | C10: 0.00069363426 | D10: 0.00085243056 | E10: 0.00071979167 | F10: 0.0017252315 | G10: 0.0015210648 | H10: 0.00035532407 | I10: 0.00058472222 | J10: 0.00072893519 | K10: 0.00062210648 | L10: 0.001496412 | M10: 0.0013346065
A11: =A10+1 -> 2006 | B11: 0.00041203704 | C11: 0.00069363426 | D11: 0.00085243056 | E11: 0.00071979167 | F11: 0.0017252315 | G11: 0.0015210648 | H11: 0.00035532407 | I11: 0.00058425926 | J11: 0.00071458333 | K11: 0.00062210648 | L11: 0.001496412 | M11: 0.0013346065
A12: =A11+1 -> 2007 | B12: 0.00040810185 | C12: 0.00065891204 | D12: 0.00084236111 | E12: 0.00071979167 | F12: 0.0017197917 | G12: 0.0015043981 | H12: 0.00035520833 | I12: 0.00058425926 | J12: 0.00073657407 | K12: 0.00062210648 | L12: 0.001496412 | M12: 0.0013346065
A13: =A12+1 -> 2008 | B13: 0.00040810185 | C13: 0.00065891204 | D13: 0.00084236111 | E13: 0.00071712963 | F13: 0.0017197917 | G13: 0.0014934028 | H13: 0.0003412037 | I13: 0.00057280093 | J13: 0.00072615741 | K13: 0.00062210648 | L13: 0.001496412 | M13: 0.0013346065
A14: =A13+1 -> 2009 | B14: 0.00040810185 | C14: 0.00065891204 | D14: 0.00084236111 | E14: 0.00070150463 | F14: 0.0017197917 | G14: 0.0014934028 | H14: 0.0003412037 | I14: 0.00057199074 | J14: 0.00071435185 | K14: 0.00062210648 | L14: 0.001496412 | M14: 0.0013346065
A15: =A14+1 -> 2010 | B15: 0.00040810185 | C15: 0.00065289352 | D15: 0.00084236111 | E15: 0.00070150463 | F15: 0.0017197917 | G15: 0.0014106481 | H15: 0.0003349537 | I15: 0.00055972222 | J15: 0.00069189815 | K15: 0.00062210648 | L15: 0.001496412 | M15: 0.0013306713
A16: =A15+1 -> 2011 | B16: 0.00040810185 | C16: 0.00065289352 | D16: 0.00084178241 | E16: 0.00070150463 | F16: 0.0017197917 | G16: 0.0014106481 | H16: 0.0003349537 | I16: 0.00055972222 | J16: 0.00069189815 | K16: 0.00062210648 | L16: 0.001496412 | M16: 0.0013306713
A17: =A16+1 -> 2012 | B17: 0.00040810185 | C17: 0.0006525463 | D17: 0.00084027778 | E17: 0.00070011574 | F17: 0.0016951389 | G17: 0.0014106481 | H17: 0.0003349537 | I17: 0.00055416667 | J17: 0.00069189815 | K17: 0.00061273148 | L17: 0.0014798611 | M17: 0.0013306713
A18: =A17+1 -> 2013 | B18: 0.00040810185 | C18: 0.0006525463 | D18: 0.0008244213 | E18: 0.00069224537 | F18: 0.0016730324 | G18: 0.0014106481 | H18: 0.0003349537 | I18: 0.0005375 | J18: 0.00069189815 | K18: 0.00059444444 | L18: 0.0014798611 | M18: 0.001312963
... A32: =A31+1 -> 2027 | B32: 0.00036435185 | C32: 0.00057060185 | D32: 0.00073715278 | E32: 0.00062731481 | F32: 0.0015748843 | G32: 0.0014106481 | H32: 0.00031481481 | I32: 0.00050104167 | J32: 0.00066481481 | K32: 0.00055185185 | L32: 0.0014233796 | M32: 0.0012931713

Sheet DP
A1: Tabellen Name | B1: Geschlecht | C1: Mindest alter | D1: Maximales Alter | E1: Qualizeitraum anfang | F1: Qualizeitraum Ende | G1: Letzter Wettkampf am | H1: Wertung | I1: Landesverband | J1: OMS | K1: Pool-Länge | L1: Regelwerk | M1: Referenz | N1: Referenz Jahr | O1: Mindest Punktzahl | P1: Mindest Disziplinen | Q1: 3-Kampf Regel | R1: Anzahl Nominierte | S1: Anzahl Nachrücker | T1: Seiten Anzahl | U1: Absagen
A2: Weiblich (2026 findet kein DP statt) | B2: w | C2: 15 | D2: 50 | E2: 1.11.Jahr - 1 | F2: 30.10.Jahr | G2: 1.1.Jahr | H2: 4-Kampf | I2: BA | J2: Nein | M2: WR-Open | N2: Jahr | O2: 0 | P2: 3 | Q2: Ja | R2: 6 | S2: 2 | T2: 10 | U2: Regina Blonski
A3: Männlich (2026 findet kein DP statt) | B3: m | C3: 15 | D3: 50 | E3: 1.11.Jahr - 1 | F3: 30.10.Jahr | G3: 1.1.Jahr | H3: 4-Kampf | I3: BA | J3: Nein | M3: WR-Open | N3: Jahr | O3: 0 | P3: 3 | Q3: Ja | R3: 6 | S3: 2 | T3: 10 | U3: Daniel Bittighofer, Roland Konietzny

Sheet BP
A1: Tabellen Name | B1: Geschlecht | C1: Mindest alter | D1: Maximales Alter | E1: Qualizeitraum anfang | F1: Qualizeitraum Ende | G1: Letzter Wettkampf am | H1: Wertung | I1: Landesverband | J1: OMS | K1: Pool-Länge | L1: Regelwerk | M1: Referenz | N1: Referenz Jahr | O1: Mindest Punktzahl | P1: Mindest Disziplinen | Q1: 3-Kampf Regel | R1: Anzahl Nominierte | S1: Anzahl Nachrücker | T1: Seiten Anzahl | U1: Absagen
A2: Weiblich Offen | B2: w | C2: 19 | D2: 50 | E2: 20.7.Jahr - 1 | F2: 30.6.Jahr | G2: 1.1.Jahr | H2: 4-Kampf | I2: BA | J2: Nein | M2: WR-Open | N2: Jahr + 1 | O2: 0 | P2: 3 | Q2: Nein | R2: 0 | S2: 0 | T2: 10 | U2: Regina Blonski
A3: Männlich Offen | B3: m | C3: 19 | D3: 50 | E3: 20.7.Jahr - 1 | F3: 30.6.Jahr | G3: 1.1.Jahr | H3: 4-Kampf | I3: BA | J3: Nein | M3: WR-Open | N3: Jahr + 1 | O3: 0 | P3: 3 | Q3: Nein | R3: 0 | S3: 0 | T3: 10 | U3: Daniel Bittighofer, Roland Konietzny
A4: Weiblich 17/18 | B4: w | C4: 17 | D4: 18 | E4: 20.7.Jahr - 1 | F4: 30.6.Jahr | G4: 1.1.Jahr | H4: 4-Kampf | I4: BA | J4: Nein | M4: WR-Open | N4: Jahr + 1 | O4: 0 | P4: 3 | Q4: Nein | R4: 0 | S4: 0 | T4: 10 | U4: Lara Ramackers, Lina Weidmann
A5: Männlich 17/18 | B5: m | C5: 17 | D5: 18 | E5: 20.7.Jahr - 1 | F5: 30.6.Jahr | G5: 1.1.Jahr | H5: 4-Kampf | I5: BA | J5: Nein | M5: WR-Open | N5: Jahr + 1 | O5: 0 | P5: 3 | Q5: Nein | R5: 0 | S5: 0 | T5: 10
A6: Weiblich 15/16 | B6: w | C6: 15 | D6: 16 | E6: 20.7.Jahr - 1 | F6: 30.6.Jahr | G6: 1.1.Jahr | H6: 4-Kampf | I6: BA | J6: Nein | M6: WR-Open | N6: Jahr + 1 | O6: 0 | P6: 3 | Q6: Nein | R6: 0 | S6: 0 | T6: 10
A7: Männlich 15/16 | B7: m | C7: 15 | D7: 16 | E7: 20.7.Jahr - 1 | F7: 30.6.Jahr | G7: 1.1.Jahr | H7: 4-Kampf | I7: BA | J7: Nein | M7: WR-Open | N7: Jahr + 1 | O7: 0 | P7: 3 | Q7: Nein | R7: 0 | S7: 0 | T7: 10

Sheet DEM
A1: Tabellen Name | B1: Geschlecht | C1: Mindest Alter | D1: Maximales Alter | E1: Qualizeitraum anfang | F1: Qualizeitraum Ende | G1: Letzter Wettkampf am | H1: Landesverband | I1: OMS | J1: Pool-Länge | K1: Regelwerk | L1: Seiten Anzahl | M1: PZ1 - 50m Retten | N1: PZ1 - 100m Retten | O1: PZ1 - 100m Kombi | P1: PZ1 - 100m Lifesaver | Q1: PZ1 - 200m Super-Lifesaver | R1: PZ1 - 200m Hindernis | S1: PZ2 - 50m Retten | T1: PZ2 - 100m Retten | U1: PZ2 - 100m Kombi | V1: PZ2 - 100m Lifesaver | W1: PZ2 - 200m Super-Lifesaver | X1: PZ2 - 200m Hindernis
A2: Weiblich U17 | B2: w | C2: 15 | D2: 16 | E2: 45658 | F2: 46113 | G2: 45658 | H2: BA | I2: Ja | L2: 10 | M2: 0.00048136574 | N2: 0.00080497685 | O2: 0.0010570602 | P2: 0.00085497685 | Q2: 0.0020892361 | R2: 0.001840162 | S2: 0.00050462963 | T2: 0.00085474537 | U2: 0.0011590278 | V2: 0.00089409722 | W2: 0.0022304398 | X2: 0.0019623843
A3: Männlich U17 | B3: m | C3: 15 | D3: 16 | E3: 45658 | F3: 46113 | G3: 45658 | H3: BA | I3: Ja | L3: 10 | M3: 0.00042962963 | N3: 0.00071435185 | O3: 0.00097106481 | P3: 0.0007693287 | Q3: 0.0018946759 | R3: 0.0016849537 | S3: 0.00045416667 | T3: 0.00076006944 | U3: 0.0010402778 | V3: 0.00081701389 | W3: 0.0020715278 | X3: 0.0018121528
A4: Weiblich U19 | B4: w | C4: 17 | D4: 18 | E4: 45658 | F4: 46113 | G4: 45658 | H4: BA | I4: Ja | L4: 10 | M4: 0.00047048611 | N4: 0.00078125 | O4: 0.0010002315 | P4: 0.00082349537 | Q4: 0.0019892361 | R4: 0.001884838 | S4: 0.00050428241 | T4: 0.000828125 | U4: 0.0010603009 | V4: 0.00087291667 | W4: 0.0021085648 | X4: 0.0019979167
A5: Männlich U19 | B5: m | C5: 17 | D5: 18 | E5: 45658 | F5: 46113 | G5: 45658 | H5: BA | I5: Ja | L5: 10 | M5: 0.00039583333 | N5: 0.00065960648 | O5: 0.00087384259 | P5: 0.00072835648 | Q5: 0.0017810185 | R5: 0.0016655093 | S5: 0.00041574074 | T5: 0.00069918981 | U5: 0.00092627315 | V5: 0.00077210648 | W5: 0.0018949074 | X5: 0.0017653935
A6: Weiblich Offen | B6: w | C6: 19 | D6: 100 | E6: 45658 | F6: 46113 | G6: 45658 | H6: BA | I6: Ja | L6: 10 | M6: 0.00045150463 | N6: 0.00072407407 | O6: 0.0010059028 | P6: 0.00076840278 | Q6: 0.0019185185 | R6: 0.0017923611 | S6: 0.00047858796 | T6: 0.00076747685 | U6: 0.0010662037 | V6: 0.00081446759 | W6: 0.0020336806 | X6: 0.0018998843
A7: Männlich Offen | B7: m | C7: 19 | D7: 100 | E7: 45658 | F7: 46113 | G7: 45658 | H7: BA | I7: Ja | L7: 10 | M7: 0.00036493056 | N7: 0.00057962963 | O7: 0.00078923611 | P7: 0.00063819444 | Q7: 0.0016078704 | R7: 0.0015675926 | S7: 0.00038645833 | T7: 0.00061435185 | U7: 0.00083657407 | V7: 0.00067650463 | W7: 0.0017043981 | X7: 0.0016616898

Sheet JRP
A1: Tabellen Name | B1: Geschlecht | C1: Mindest Alter | D1: Maximales Alter | E1: Qualizeitraum anfang | F1: Qualizeitraum Ende | G1: Letzter Wettkampf am | H1: Landesverband | I1: OMS | J1: Pool-Länge | K1: Regelwerk | L1: Seiten Anzahl | M1: PZ1 - 50m Retten | N1: PZ1 - 100m Retten | O1: PZ1 - 100m Kombi | P1: PZ1 - 100m Lifesaver | Q1: PZ1 - 200m Super-Lifesaver | R1: PZ1 - 200m Hindernis | S1: PZ2 - 50m Retten | T1: PZ2 - 100m Retten | U1: PZ2 - 100m Kombi | V1: PZ2 - 100m Lifesaver | W1: PZ2 - 200m Super-Lifesaver | X1: PZ2 - 200m Hindernis
A2: JRP (TEST) Weiblich | B2: w | C2: 15 | D2: 18 | E2: 45658 | F2: 46174 | G2: 45658 | H2: BA | I2: Nein | L2: 10 | M2: 0.0004681713 | N2: 0.00074872685 | O2: 0.00099224537 | P2: 0.00078888889 | Q2: 0.0019605324 | R2: 0.0017837963 | S2: 0.00048032407 | T2: 0.00078599537 | U2: 0.0010240741 | V2: 0.00082766204 | W2: 0.0020114583 | X2: 0.0018332176
A3: JRP (TEST) Männlich | B3: m | C3: 15 | D3: 18 | E3: 45658 | F3: 46174 | G3: 45658 | H3: BA | I3: Nein | L3: 10 | M3: 0.00039178241 | N3: 0.00063101852 | O3: 0.00085555556 | P3: 0.00070196759 | Q3: 0.0017359954 | R3: 0.0016295139 | S3: 0.00041747685 | T3: 0.00067627315 | U3: 0.00089861111 | V3: 0.00072384259 | W3: 0.0018050926 | X3: 0.0017003472

Sheet LK
A1: Tabellen Name | B1: Geschlecht | C1: Mindest Alter | D1: Maximales Alter | E1: Qualizeitraum anfang | F1: Qualizeitraum Ende | G1: Letzter Wettkampf am | H1: Landesverband | I1: OMS | J1: Pool-Länge | K1: Regelwerk | L1: Seiten Anzahl | M1: mind. erreichte Normen | N1: PZ - 50m Retten | O1: PZ - 100m Retten | P1: PZ - 100m Kombi | Q1: PZ - 100m Lifesaver | R1: PZ - 200m Super-Lifesaver | S1: PZ - 200m Hindernis | T1: LMS | U1: DMM | V1: DEM | W1: JRP | X1: DMO | Y1: DMO Ocean | Z1: Trophy | AA1: Ocean Perf | AB1: Filcow | AC1: WM | AD1: EM | AE1: JWM | AF1: JEM
A2: LK2 - Weiblich | B2: w | C2: 18 | D2: 18 | E2: 46023 | F2: 46388 | G2: 46023 | H2: BA | I2: Ja | L2: 10 | M2: 2 | N2: ='NK-LK Transf.'!BQ12 -> 0.0005378287 | O2: ='NK-LK Transf.'!BQ14 -> 0.00081398148 | P2: ='NK-LK Transf.'!BQ13 -> 0.0011029722 | Q2: ='NK-LK Transf.'!BQ15 -> 0.00090261806 | R2: ='NK-LK Transf.'!BQ17 -> 0.0021334236 | S2: ='NK-LK Transf.'!BQ16 -> 0.0019327963
A3: LK2 - Weiblich | B3: w | C3: 17 | D3: 17 | E3: 46023 | F3: 46388 | G3: 46023 | H3: BA | I3: Ja | L3: 10 | M3: 2 | N3: ='NK-LK Transf.'!BP12 -> 0.00055107639 | O3: ='NK-LK Transf.'!BP14 -> 0.00083037037 | P3: ='NK-LK Transf.'!BP13 -> 0.0011436713 | Q3: ='NK-LK Transf.'!BP15 -> 0.00092269444 | R3: ='NK-LK Transf.'!BP17 -> 0.0021813611 | S3: ='NK-LK Transf.'!BP16 -> 0.0019621597
A4: LK2 - Weiblich | B4: w | C4: 14 | D4: 16 | E4: 46023 | F4: 46388 | G4: 46023 | H4: BA | I4: Ja | L4: 10 | M4: 2 | N4: ='NK-LK Transf.'!BO12 -> 0.00056332031 | O4: ='NK-LK Transf.'!BO14 -> 0.00084539352 | P4: ='NK-LK Transf.'!BO13 -> 0.0011842338 | Q4: ='NK-LK Transf.'!BO15 -> 0.00094126852 | R4: ='NK-LK Transf.'!BO17 -> 0.002229162 | S4: ='NK-LK Transf.'!BO16 -> 0.0019916597
A5: LK2 - Männlich | B5: m | C5: 18 | D5: 18 | E5: 46023 | F5: 46388 | G5: 46023 | H5: BA | I5: Ja | L5: 10 | M5: 2 | N5: ='NK-LK Transf.'!BE12 -> 0.00044791667 | O5: ='NK-LK Transf.'!BE14 -> 0.00070736111 | P5: ='NK-LK Transf.'!BE13 -> 0.00096125 | Q5: ='NK-LK Transf.'!BE15 -> 0.00080180556 | R5: ='NK-LK Transf.'!BE17 -> 0.0019945833 | S5: ='NK-LK Transf.'!BE16 -> 0.0018218056
A6: LK2 - Männlich | B6: m | C6: 17 | D6: 17 | E6: 46023 | F6: 46388 | G6: 46023 | H6: BA | I6: Ja | L6: 10 | M6: 2 | N6: ='NK-LK Transf.'!BD12 -> 0.00046194444 | O6: ='NK-LK Transf.'!BD14 -> 0.00072763889 | P6: ='NK-LK Transf.'!BD13 -> 0.001 | Q6: ='NK-LK Transf.'!BD15 -> 0.00083263889 | R6: ='NK-LK Transf.'!BD17 -> 0.00205875 | S6: ='NK-LK Transf.'!BD16 -> 0.0018773611
A7: LK2 - Männlich | B7: m | C7: 14 | D7: 16 | E7: 46023 | F7: 46388 | G7: 46023 | H7: BA | I7: Ja | L7: 10 | M7: 2 | N7: ='NK-LK Transf.'!BC12 -> 0.00047138889 | O7: ='NK-LK Transf.'!BC14 -> 0.00074152778 | P7: ='NK-LK Transf.'!BC13 -> 0.0010176389 | Q7: ='NK-LK Transf.'!BC15 -> 0.00085375 | R7: ='NK-LK Transf.'!BC17 -> 0.0021025 | S7: ='NK-LK Transf.'!BC16 -> 0.0019152778
A8: LK1 - Weiblich | B8: w | C8: 23 | D8: 50 | E8: 46023 | F8: 46388 | G8: 46023 | H8: BA | I8: Ja | L8: 10 | M8: 2 | N8: ='NK-LK Transf.'!BV12 -> 0.00047436458 | O8: ='NK-LK Transf.'!BV14 -> 0.00073382292 | P8: ='NK-LK Transf.'!BV13 -> 0.00097080208 | Q8: ='NK-LK Transf.'!BV15 -> 0.00080545833 | R8: ='NK-LK Transf.'!BV17 -> 0.0019667917 | S8: ='NK-LK Transf.'!BV16 -> 0.0018239271
A9: LK1 - Weiblich | B9: w | C9: 20 | D9: 22 | E9: 46023 | F9: 46388 | G9: 46023 | H9: BA | I9: Ja | L9: 10 | M9: 2 | N9: ='NK-LK Transf.'!BU12 -> 0.00049196875 | O9: ='NK-LK Transf.'!BU14 -> 0.00075576042 | P9: ='NK-LK Transf.'!BU13 -> 0.0010057396 | Q9: ='NK-LK Transf.'!BU15 -> 0.00083227083 | R9: ='NK-LK Transf.'!BU17 -> 0.0020094479 | S9: ='NK-LK Transf.'!BU16 -> 0.0018506042
A10: LK1 - Weiblich | B10: w | C10: 14 | D10: 19 | E10: 46023 | F10: 46388 | G10: 46023 | H10: BA | I10: Ja | L10: 10 | M10: 2 | N10: ='NK-LK Transf.'!BT12 -> 0.0005159375 | O10: ='NK-LK Transf.'!BT14 -> 0.00078582292 | P10: ='NK-LK Transf.'!BT13 -> 0.0010534062 | Q10: ='NK-LK Transf.'!BT15 -> 0.00086883333 | R10: ='NK-LK Transf.'!BT17 -> 0.0020678125 | S10: ='NK-LK Transf.'!BT16 -> 0.0018871667
A11: LK1 - Männlich | B11: m | C11: 23 | D11: 50 | E11: 46023 | F11: 46388 | G11: 46023 | H11: BA | I11: Ja | L11: 10 | M11: 2 | N11: ='NK-LK Transf.'!BJ12 -> 0.00039324537 | O11: ='NK-LK Transf.'!BJ14 -> 0.00062564815 | P11: ='NK-LK Transf.'!BJ13 -> 0.00083428704 | Q11: ='NK-LK Transf.'!BJ15 -> 0.0006880787 | R11: ='NK-LK Transf.'!BJ17 -> 0.0017890046 | S11: ='NK-LK Transf.'!BJ16 -> 0.0016026528
A12: LK1 - Männlich | B12: m | C12: 20 | D12: 22 | E12: 46023 | F12: 46388 | G12: 46023 | H12: BA | I12: Ja | L12: 10 | M12: 2 | N12: ='NK-LK Transf.'!BI12 -> 0.00040693981 | O12: ='NK-LK Transf.'!BI14 -> 0.00064565278 | P12: ='NK-LK Transf.'!BI13 -> 0.00086691204 | Q12: ='NK-LK Transf.'!BI15 -> 0.00071788426 | R12: ='NK-LK Transf.'!BI17 -> 0.001845125 | S12: ='NK-LK Transf.'!BI16 -> 0.001657162
A13: LK1 - Männlich | B13: m | C13: 14 | D13: 19 | E13: 46023 | F13: 46388 | G13: 46023 | H13: BA | I13: Ja | L13: 10 | M13: 2 | N13: ='NK-LK Transf.'!BH12 -> 0.00041888889 | O13: ='NK-LK Transf.'!BH14 -> 0.00066324074 | P13: ='NK-LK Transf.'!BH13 -> 0.000895375 | Q13: ='NK-LK Transf.'!BH15 -> 0.00074393056 | R13: ='NK-LK Transf.'!BH17 -> 0.00186325 | S13: ='NK-LK Transf.'!BH16 -> 0.0017049583
A14: NK2 - Weiblich | B14: w | C14: 18 | D14: 18 | E14: 45992 | F14: 46388 | G14: 45992 | H14: BA | I14: Ja | J14: 50 | L14: 10 | M14: 1 | N14: ='NK-LK Transf.'!Q12 -> 0.00045578704 | O14: ='NK-LK Transf.'!Q14 -> 0.00068981481 | P14: ='NK-LK Transf.'!Q13 -> 0.00093472222 | Q14: ='NK-LK Transf.'!Q15 -> 0.00076493056 | R14: ='NK-LK Transf.'!Q17 -> 0.0018079861 | S14: ='NK-LK Transf.'!Q16 -> 0.001637963 | X14: 4-6 | Y14: 6-9 | Z14: 1-8 | AE14: 1000 | AF14: 1000
A15: NK2 - Weiblich | B15: w | C15: 17 | D15: 17 | E15: 45992 | F15: 46388 | G15: 45992 | H15: BA | I15: Ja | J15: 50 | L15: 10 | M15: 1 | N15: ='NK-LK Transf.'!P12 -> 0.00046701389 | O15: ='NK-LK Transf.'!P14 -> 0.0007037037 | P15: ='NK-LK Transf.'!P13 -> 0.00096921296 | Q15: ='NK-LK Transf.'!P15 -> 0.00078194444 | R15: ='NK-LK Transf.'!P17 -> 0.0018486111 | S15: ='NK-LK Transf.'!P16 -> 0.0016628472 | U15: 1-3 | X15: 4-6 | Y15: 6-9 | Z15: 1-8 | AE15: 1000 | AF15: 1000
A16: NK2 - Weiblich | B16: w | C16: 14 | D16: 16 | E16: 45992 | F16: 46388 | G16: 45992 | H16: BA | I16: Ja | J16: 50 | L16: 10 | M16: 1 | N16: ='NK-LK Transf.'!O12 -> 0.00047743056 | O16: ='NK-LK Transf.'!O14 -> 0.00071643519 | P16: ='NK-LK Transf.'!O13 -> 0.001003588 | Q16: ='NK-LK Transf.'!O15 -> 0.00079768519 | R16: ='NK-LK Transf.'!O17 -> 0.0018891204 | S16: ='NK-LK Transf.'!O16 -> 0.0016878472 | U16: 1-3 | X16: 4-6 | Y16: 6-9 | Z16: 1-8 | AE16: 1000 | AF16: 1000
A17: NK2 - Männlich | B17: m | C17: 18 | D17: 18 | E17: 45992 | F17: 46388 | G17: 45992 | H17: BA | I17: Ja | J17: 50 | L17: 10 | M17: 1 | N17: ='NK-LK Transf.'!E12 -> 0.00037326389 | O17: ='NK-LK Transf.'!E14 -> 0.00058946759 | P17: ='NK-LK Transf.'!E13 -> 0.00080104167 | Q17: ='NK-LK Transf.'!E15 -> 0.0006681713 | R17: ='NK-LK Transf.'!E17 -> 0.0016621528 | S17: ='NK-LK Transf.'!E16 -> 0.0015181713 | X17: 4-6 | Y17: 6-9 | Z17: 1-8 | AE17: 1000 | AF17: 1000
A18: NK2 - Männlich | B18: m | C18: 17 | D18: 17 | E18: 45992 | F18: 46388 | G18: 45992 | H18: BA | I18: Ja | J18: 50 | L18: 10 | M18: 1 | N18: ='NK-LK Transf.'!D12 -> 0.0003849537 | O18: ='NK-LK Transf.'!D14 -> 0.00060636574 | P18: ='NK-LK Transf.'!D13 -> 0.00083333333 | Q18: ='NK-LK Transf.'!D15 -> 0.00069386574 | R18: ='NK-LK Transf.'!D17 -> 0.001715625 | S18: ='NK-LK Transf.'!D16 -> 0.0015644676 | U18: 1-3 | X18: 4-6 | Y18: 6-9 | Z18: 1-8 | AE18: 1000 | AF18: 1000
A19: NK2 - Männlich | B19: m | C19: 14 | D19: 16 | E19: 45992 | F19: 46388 | G19: 45992 | H19: BA | I19: Ja | J19: 50 | L19: 10 | M19: 1 | N19: ='NK-LK Transf.'!C12 -> 0.00039282407 | O19: ='NK-LK Transf.'!C14 -> 0.00061793981 | P19: ='NK-LK Transf.'!C13 -> 0.00084803241 | Q19: ='NK-LK Transf.'!C15 -> 0.00071145833 | R19: ='NK-LK Transf.'!C17 -> 0.0017520833 | S19: ='NK-LK Transf.'!C16 -> 0.0015960648 | U19: 1-3 | X19: 4-6 | Y19: 6-9 | Z19: 1-8 | AE19: 1000 | AF19: 1000
A20: NK1 - Weiblich | B20: w | C20: 23 | D20: 24 | E20: 45992 | F20: 46388 | G20: 45992 | H20: BA | I20: Ja | J20: 50 | L20: 10 | M20: 1 | N20: ='NK-LK Transf.'!V12 -> 0.00040543981 | O20: ='NK-LK Transf.'!V14 -> 0.00062719907 | P20: ='NK-LK Transf.'!V13 -> 0.00082974537 | Q20: ='NK-LK Transf.'!V15 -> 0.00068842593 | R20: ='NK-LK Transf.'!V17 -> 0.0016810185 | S20: ='NK-LK Transf.'!V16 -> 0.001558912 | X20: 4-6 | Y20: 6-9 | AA20: 6-10 | AB20: 1-3 | AD20: 9-16
A21: NK1 - Weiblich | B21: w | C21: 20 | D21: 22 | E21: 45992 | F21: 46388 | G21: 45992 | H21: BA | I21: Ja | J21: 50 | L21: 10 | M21: 1 | N21: ='NK-LK Transf.'!U12 -> 0.00042048611 | O21: ='NK-LK Transf.'!U14 -> 0.00064594907 | P21: ='NK-LK Transf.'!U13 -> 0.00085960648 | Q21: ='NK-LK Transf.'!U15 -> 0.00071134259 | R21: ='NK-LK Transf.'!U17 -> 0.0017174769 | S21: ='NK-LK Transf.'!U16 -> 0.001581713 | X21: 4-6 | Y21: 6-9 | AA21: 6-10 | AB21: 1-3 | AD21: 9-16
A22: NK1 - Weiblich | B22: w | C22: 19 | D22: 19 | E22: 45992 | F22: 46388 | G22: 45992 | H22: BA | I22: Ja | J22: 50 | L22: 10 | M22: 1 | N22: ='NK-LK Transf.'!T12 -> 0.00044097222 | O22: ='NK-LK Transf.'!T14 -> 0.00067164352 | P22: ='NK-LK Transf.'!T13 -> 0.00090034722 | Q22: ='NK-LK Transf.'!T15 -> 0.00074259259 | R22: ='NK-LK Transf.'!T17 -> 0.0017673611 | S22: ='NK-LK Transf.'!T16 -> 0.001612963 | U22: 1-3 | X22: 1-3 | Y22: 1-5 | AA22: 6-10 | AB22: 1-8 | AE22: 1-8 | AF22: 1-8
A23: NK1 - Weiblich | B23: w | C23: 18 | D23: 18 | E23: 45992 | F23: 46388 | G23: 45992 | H23: BA | I23: Ja | J23: 50 | L23: 10 | M23: 1 | N23: ='NK-LK Transf.'!S12 -> 0.00045138889 | O23: ='NK-LK Transf.'!S14 -> 0.00068449074 | P23: ='NK-LK Transf.'!S13 -> 0.00092094907 | Q23: ='NK-LK Transf.'!S15 -> 0.00075833333 | R23: ='NK-LK Transf.'!S17 -> 0.0017916667 | S23: ='NK-LK Transf.'!S16 -> 0.0016278935 | U23: 1-3 | X23: 1-3 | Y23: 1-5 | AA23: 6-10 | AB23: 1-8 | AE23: 1-8 | AF23: 1-8
A24: NK1 - Weiblich | B24: w | C24: 14 | D24: 17 | E24: 45992 | F24: 46388 | G24: 45992 | H24: BA | I24: Ja | J24: 50 | L24: 10 | M24: 1 | N24: ='NK-LK Transf.'!R12 -> 0.00045868056 | O24: ='NK-LK Transf.'!R14 -> 0.00069837963 | P24: ='NK-LK Transf.'!R13 -> 0.00094340278 | Q24: ='NK-LK Transf.'!R15 -> 0.00077534722 | R24: ='NK-LK Transf.'!R17 -> 0.0018180556 | S24: ='NK-LK Transf.'!R16 -> 0.001644213 | X24: 1-3 | Y24: 1-5 | AA24: 6-10 | AB24: 1-8 | AE24: 1-8 | AF24: 1-8
A25: NK1 - Männlich | B25: m | C25: 23 | D25: 24 | E25: 45992 | F25: 46388 | G25: 45992 | H25: BA | I25: Ja | J25: 50 | L25: 10 | M25: 1 | N25: ='NK-LK Transf.'!J12 -> 0.00033900463 | O25: ='NK-LK Transf.'!J14 -> 0.00053935185 | P25: ='NK-LK Transf.'!J13 -> 0.00071921296 | Q25: ='NK-LK Transf.'!J15 -> 0.0005931713 | R25: ='NK-LK Transf.'!J17 -> 0.0015422454 | S25: ='NK-LK Transf.'!J16 -> 0.0013815972 | X25: 4-6 | Y25: 6-9 | AA25: 6-10 | AB25: 1-3 | AD25: 9-16
A26: NK1 - Männlich | B26: m | C26: 20 | D26: 22 | E26: 45992 | F26: 46388 | G26: 45992 | H26: BA | I26: Ja | J26: 50 | L26: 10 | M26: 1 | N26: ='NK-LK Transf.'!I12 -> 0.00035081019 | O26: ='NK-LK Transf.'!I14 -> 0.00055659722 | P26: ='NK-LK Transf.'!I13 -> 0.00074733796 | Q26: ='NK-LK Transf.'!I15 -> 0.00061886574 | R26: ='NK-LK Transf.'!I17 -> 0.001590625 | S26: ='NK-LK Transf.'!I16 -> 0.001428588 | X26: 4-6 | Y26: 6-9 | AA26: 6-10 | AB26: 1-3 | AD26: 9-16
A27: NK1 - Männlich | B27: m | C27: 19 | D27: 19 | E27: 45992 | F27: 46388 | G27: 45992 | H27: BA | I27: Ja | J27: 50 | L27: 10 | M27: 1 | N27: ='NK-LK Transf.'!H12 -> 0.00036111111 | O27: ='NK-LK Transf.'!H14 -> 0.00057175926 | P27: ='NK-LK Transf.'!H13 -> 0.000771875 | Q27: ='NK-LK Transf.'!H15 -> 0.00064131944 | R27: ='NK-LK Transf.'!H17 -> 0.00160625 | S27: ='NK-LK Transf.'!H16 -> 0.0014697917 | U27: 1-3 | X27: 1-3 | Y27: 1-5 | AA27: 6-10 | AB27: 1-8 | AE27: 1-8 | AF27: 1-8
A28: NK1 - Männlich | B28: m | C28: 18 | D28: 18 | E28: 45992 | F28: 46388 | G28: 45992 | H28: BA | I28: Ja | J28: 50 | L28: 10 | M28: 1 | N28: ='NK-LK Transf.'!G12 -> 0.00036747685 | O28: ='NK-LK Transf.'!G14 -> 0.00058101852 | P28: ='NK-LK Transf.'!G13 -> 0.00078715278 | Q28: ='NK-LK Transf.'!G15 -> 0.00065532407 | R28: ='NK-LK Transf.'!G17 -> 0.0016241898 | S28: ='NK-LK Transf.'!G16 -> 0.0014950231 | U28: 1-3 | X28: 1-3 | Y28: 1-5 | AA28: 6-10 | AB28: 1-8 | AE28: 1-8 | AF28: 1-8
A29: NK1 - Männlich | B29: m | C29: 14 | D29: 17 | E29: 45992 | F29: 46388 | G29: 45992 | H29: BA | I29: Ja | J29: 50 | L29: 10 | M29: 1 | N29: ='NK-LK Transf.'!F12 -> 0.00037430556 | O29: ='NK-LK Transf.'!F14 -> 0.00059097222 | P29: ='NK-LK Transf.'!F13 -> 0.00080358796 | Q29: ='NK-LK Transf.'!F15 -> 0.00067048611 | R29: ='NK-LK Transf.'!F17 -> 0.0016435185 | S29: ='NK-LK Transf.'!F16 -> 0.001522338 | X29: 1-3 | Y29: 1-5 | AA29: 6-10 | AB29: 1-8 | AE29: 1-8 | AF29: 1-8
A30: PK - Weiblich | B30: w | C30: 25 | D30: 50 | E30: 45992 | F30: 46388 | G30: 45992 | H30: BA | I30: Ja | J30: 50 | L30: 10 | M30: 1 | N30: ='NK-LK Transf.'!Z12 -> 0.00040069444 | O30: ='NK-LK Transf.'!Z14 -> 0.0006212963 | P30: ='NK-LK Transf.'!Z13 -> 0.00082037037 | Q30: ='NK-LK Transf.'!Z15 -> 0.00068125 | R30: ='NK-LK Transf.'!Z17 -> 0.0016695602 | S30: ='NK-LK Transf.'!Z16 -> 0.0015517361 | X30: 1-3 | Y30: 1-5 | AA30: 1-5 | AC30: 9-16 | AD30: 4-8
A31: PK - Weiblich | B31: w | C31: 22 | D31: 24 | E31: 45992 | F31: 46388 | G31: 45992 | H31: BA | I31: Ja | J31: 50 | L31: 10 | M31: 1 | N31: ='NK-LK Transf.'!Y12 -> 0.00040381944 | O31: ='NK-LK Transf.'!Y14 -> 0.00062523148 | P31: ='NK-LK Transf.'!Y13 -> 0.00082662037 | Q31: ='NK-LK Transf.'!Y15 -> 0.00068611111 | R31: ='NK-LK Transf.'!Y17 -> 0.0016771991 | S31: ='NK-LK Transf.'!Y16 -> 0.0015564815 | X31: 1-3 | Y31: 1-5 | AA31: 1-5 | AC31: 9-16 | AD31: 4-8
A32: PK - Weiblich | B32: w | C32: 21 | D32: 21 | E32: 45992 | F32: 46388 | G32: 45992 | H32: BA | I32: Ja | J32: 50 | L32: 10 | M32: 1 | N32: ='NK-LK Transf.'!X12 -> 0.00041331019 | O32: ='NK-LK Transf.'!X14 -> 0.00063703704 | P32: ='NK-LK Transf.'!X13 -> 0.00084548611 | Q32: ='NK-LK Transf.'!X15 -> 0.00070046296 | R32: ='NK-LK Transf.'!X17 -> 0.0017002315 | S32: ='NK-LK Transf.'!X16 -> 0.0015709491 | X32: 1-3 | Y32: 1-5 | AA32: 1-5 | AC32: 9-16 | AD32: 4-8
A33: PK - Weiblich | B33: w | C33: 20 | D33: 20 | E33: 45992 | F33: 46388 | G33: 45992 | H33: BA | I33: Ja | J33: 50 | L33: 10 | M33: 1 | N33: ='NK-LK Transf.'!W12 -> 0.00042118056 | O33: ='NK-LK Transf.'!W14 -> 0.00064699074 | P33: ='NK-LK Transf.'!W13 -> 0.00086111111 | Q33: ='NK-LK Transf.'!W15 -> 0.0007125 | R33: ='NK-LK Transf.'!W17 -> 0.0017194444 | S33: ='NK-LK Transf.'!W16 -> 0.0015829861 | X33: 1-3 | Y33: 1-5 | AA33: 1-5 | AC33: 9-16 | AD33: 4-8
A34: PK - Männlich | B34: m | C34: 25 | D34: 50 | E34: 45992 | F34: 46388 | G34: 45992 | H34: BA | I34: Ja | J34: 50 | L34: 10 | M34: 1 | N34: ='NK-LK Transf.'!N12 -> 0.00033599537 | O34: ='NK-LK Transf.'!N14 -> 0.00053506944 | P34: ='NK-LK Transf.'!N13 -> 0.00071215278 | Q34: ='NK-LK Transf.'!N15 -> 0.00058680556 | R34: ='NK-LK Transf.'!N17 -> 0.0014912037 | S34: ='NK-LK Transf.'!N16 -> 0.0013697917 | X34: 1-3 | Y34: 1-5 | AA34: 1-5 | AC34: 9-16 | AD34: 4-8
A35: PK - Männlich | B35: m | C35: 22 | D35: 24 | E35: 45992 | F35: 46388 | G35: 45992 | H35: BA | I35: Ja | J35: 50 | L35: 10 | M35: 1 | N35: ='NK-LK Transf.'!M12 -> 0.00033796296 | O35: ='NK-LK Transf.'!M14 -> 0.00053796296 | P35: ='NK-LK Transf.'!M13 -> 0.00071678241 | Q35: ='NK-LK Transf.'!M15 -> 0.00059108796 | R35: ='NK-LK Transf.'!M17 -> 0.0015002315 | S35: ='NK-LK Transf.'!M16 -> 0.001377662 | X35: 1-3 | Y35: 1-5 | AA35: 1-5 | AC35: 9-16 | AD35: 4-8
A36: PK - Männlich | B36: m | C36: 21 | D36: 21 | E36: 45992 | F36: 46388 | G36: 45992 | H36: BA | I36: Ja | J36: 50 | L36: 10 | M36: 1 | N36: ='NK-LK Transf.'!L12 -> 0.00034386574 | O36: ='NK-LK Transf.'!L14 -> 0.00054652778 | P36: ='NK-LK Transf.'!L13 -> 0.00073090278 | Q36: ='NK-LK Transf.'!L15 -> 0.00060393519 | R36: ='NK-LK Transf.'!L17 -> 0.0015273148 | S36: ='NK-LK Transf.'!L16 -> 0.0014011574 | X36: 1-3 | Y36: 1-5 | AA36: 1-5 | AC36: 9-16 | AD36: 4-8
A37: PK - Männlich | B37: m | C37: 20 | D37: 20 | E37: 45992 | F37: 46388 | G37: 45992 | H37: BA | I37: Ja | J37: 50 | L37: 10 | M37: 1 | N37: ='NK-LK Transf.'!K12 -> 0.00034884259 | O37: ='NK-LK Transf.'!K14 -> 0.00055381944 | P37: ='NK-LK Transf.'!K13 -> 0.00074259259 | Q37: ='NK-LK Transf.'!K15 -> 0.00061458333 | R37: ='NK-LK Transf.'!K17 -> 0.0015498843 | S37: ='NK-LK Transf.'!K16 -> 0.0014207176 | X37: 1-3 | Y37: 1-5 | AA37: 1-5 | AC37: 9-16 | AD37: 4-8

Sheet NK-LK Transf.
A1: 2025 | B1: =CONCATENATE("in: ",YEAR(TODAY())-1," für: ", YEAR(TODAY())) -> in: 2025 für: 2026 | C1: NK2 - Männlich | F1: NK 1 - Männlich | K1: PK 1 - Männlich | O1: NK2 - Weiblich | R1: NK 1 - Weiblich | W1: PK 1 - Weiblich | AB1: =CONCATENATE("in: ",YEAR(TODAY())-1," für: ", YEAR(TODAY())) -> in: 2025 für: 2026 | AC1: NK2 - LK2 Männlich | AF1: NK1 - LK1 Männlich | AK1: PK 1 - / Männlich | AO1: NK2 - LK2 Weiblich | AR1: NK1- LK1 Weiblich | AW1: PK 1 - / Weiblich | BB1: =CONCATENATE("in: ",YEAR(TODAY())-1," für: ", YEAR(TODAY())) -> in: 2025 für: 2026 | BC1: LK2 - Männlich | BF1: LK 1 - Männlich | BK1: (PK 1 - Männlich) | BO1: LK2 - Weiblich | BR1: LK 1 - Weiblich | BW1: (PK 1 - Weiblich)
B2: Disziplinen | C2: =CONCATENATE("≤",YEAR(TODAY())-15-1) -> ≤2010 | D2: =YEAR(TODAY())-16-1 -> 2009 | E2: =YEAR(TODAY())-17-1 -> 2008 | F2: =YEAR(TODAY())-16-1 -> 2009 | G2: =YEAR(TODAY())-17-1 -> 2008 | H2: =YEAR(TODAY())-18-1 -> 2007 | I2: =CONCATENATE(YEAR(TODAY())-1-19,"-",YEAR(TODAY())-1-21) -> 2006-2004 | J2: =CONCATENATE(YEAR(TODAY())-1-22,"-",YEAR(TODAY())-1-23) -> 2003-2002 | K2: =CONCATENATE(YEAR(TODAY())-1-15,"-",YEAR(TODAY())-1-19) -> 2010-2006 | L2: =YEAR(TODAY())-20-1 -> 2005 | M2: =CONCATENATE(YEAR(TODAY())-1-21,"-",YEAR(TODAY())-1-23) -> 2004-2002 | N2: =CONCATENATE(YEAR(TODAY())-1-24,"-",YEAR(TODAY())-40-1) -> 2001-1985 | O2: =CONCATENATE("≤",YEAR(TODAY())-15-1) -> ≤2010 | P2: =YEAR(TODAY())-16-1 -> 2009 | Q2: =YEAR(TODAY())-17-1 -> 2008 | R2: =YEAR(TODAY())-16-1 -> 2009 | S2: =YEAR(TODAY())-17-1 -> 2008 | T2: =YEAR(TODAY())-18-1 -> 2007 | U2: =CONCATENATE(YEAR(TODAY())-1-19,"-",YEAR(TODAY())-1-21) -> 2006-2004 | V2: =CONCATENATE(YEAR(TODAY())-1-22,"-",YEAR(TODAY())-1-23) -> 2003-2002 | W2: =CONCATENATE(YEAR(TODAY())-1-15,"-",YEAR(TODAY())-1-19) -> 2010-2006 | X2: =YEAR(TODAY())-20-1 -> 2005 | Y2: =CONCATENATE(YEAR(TODAY())-1-21,"-",YEAR(TODAY())-1-23) -> 2004-2002 | Z2: =CONCATENATE(YEAR(TODAY())-1-24,"-",YEAR(TODAY())-50-1) -> 2001-1975 | AB2: Disziplinen | AC2: =CONCATENATE("≤",YEAR(TODAY())-15) -> ≤2011 | AD2: =YEAR(TODAY())-16 -> 2010 | AE2: =YEAR(TODAY())-17 -> 2009 | AF2: =YEAR(TODAY())-16 -> 2010 | AG2: =YEAR(TODAY())-17 -> 2009 | AH2: =YEAR(TODAY())-18 -> 2008 | AI2: =CONCATENATE(YEAR(TODAY())-19,"-",YEAR(TODAY())-21) -> 2007-2005 | AJ2: =CONCATENATE(YEAR(TODAY())-22,"-",YEAR(TODAY())-50) -> 2004-1976 | AK2: =CONCATENATE(YEAR(TODAY())-15,"-",YEAR(TODAY())-19) -> 2011-2007 | AL2: =YEAR(TODAY())-20 -> 2006 | AM2: =CONCATENATE(YEAR(TODAY())-21,"-",YEAR(TODAY())-23) -> 2005-2003 | AN2: =CONCATENATE(YEAR(TODAY())-24,"-",YEAR(TODAY())-40) -> 2002-1986 | AO2: =CONCATENATE("≤",YEAR(TODAY())-15) -> ≤2011 | AP2: =YEAR(TODAY())-16 -> 2010 | AQ2: =YEAR(TODAY())-17 -> 2009 | AR2: =YEAR(TODAY())-16 -> 2010 | AS2: =YEAR(TODAY())-17 -> 2009 | AT2: =YEAR(TODAY())-18 -> 2008 | AU2: =CONCATENATE(YEAR(TODAY())-19,"-",YEAR(TODAY())-21) -> 2007-2005 | AV2: =CONCATENATE(YEAR(TODAY())-22,"-",YEAR(TODAY())-50) -> 2004-1976 | AW2: =CONCATENATE(YEAR(TODAY())-15,"-",YEAR(TODAY())-19) -> 2011-2007 | AX2: =YEAR(TODAY())-20 -> 2006 | AY2: =CONCATENATE(YEAR(TODAY())-21,"-",YEAR(TODAY())-23) -> 2005-2003 | AZ2: =CONCATENATE(YEAR(TODAY())-24,"-",YEAR(TODAY())-40) -> 2002-1986 | BB2: Disziplinen | BC2: =CONCATENATE("≤",YEAR(TODAY())-15-1) -> ≤2010 | BD2: =YEAR(TODAY())-16-1 -> 2009 | BE2: =YEAR(TODAY())-17-1 -> 2008 | BF2: =YEAR(TODAY())-16-1 -> 2009 | BG2: =YEAR(TODAY())-17-1 -> 2008 | BH2: =YEAR(TODAY())-18-1 -> 2007 | BI2: =CONCATENATE(YEAR(TODAY())-1-19,"-",YEAR(TODAY())-1-21) -> 2006-2004 | BJ2: =CONCATENATE(YEAR(TODAY())-1-22,"-",YEAR(TODAY())-1-50) -> 2003-1975 | BK2: =CONCATENATE(YEAR(TODAY())-1-15,"-",YEAR(TODAY())-1-19) -> 2010-2006 | BL2: =YEAR(TODAY())-20-1 -> 2005 | BM2: =CONCATENATE(YEAR(TODAY())-1-21,"-",YEAR(TODAY())-1-23) -> 2004-2002 | BN2: =CONCATENATE(YEAR(TODAY())-1-24,"-",YEAR(TODAY())-40-1) -> 2001-1985 | BO2: =CONCATENATE("≤",YEAR(TODAY())-15-1) -> ≤2010 | BP2: =YEAR(TODAY())-16-1 -> 2009 | BQ2: =YEAR(TODAY())-17-1 -> 2008 | BR2: =YEAR(TODAY())-16-1 -> 2009 | BS2: =YEAR(TODAY())-17-1 -> 2008 | BT2: =YEAR(TODAY())-18-1 -> 2007 | BU2: =CONCATENATE(YEAR(TODAY())-1-19,"-",YEAR(TODAY())-1-21) -> 2006-2004 | BV2: =CONCATENATE(YEAR(TODAY())-1-22,"-",YEAR(TODAY())-1-50) -> 2003-1975 | BW2: =CONCATENATE(YEAR(TODAY())-1-15,"-",YEAR(TODAY())-1-19) -> 2010-2006 | BX2: =YEAR(TODAY())-20-1 -> 2005 | BY2: =CONCATENATE(YEAR(TODAY())-1-21,"-",YEAR(TODAY())-1-23) -> 2004-2002 | BZ2: =CONCATENATE(YEAR(TODAY())-1-24,"-",YEAR(TODAY())-40-1) -> 2001-1985
B3: 50m Retten | C3: 0.00037384259 | D3: 0.00037025463 | E3: 0.0003662037 | F3: 0.00036863426 | G3: 0.00036469907 | H3: 0.00036111111 | I3: 0.00035787037 | J3: 0.00034803241 | K3: 0.00035381944 | L3: 0.00035092593 | M3: 0.0003474537 | N3: 0.0003462963 | O3: 0.00047083333 | P3: 0.00046215278 | Q3: 0.00045300926 | R3: 0.00045868056 | S3: 0.0004494213 | T3: 0.00044097222 | U3: 0.0004337963 | V3: 0.00041157407 | W3: 0.00042465278 | X3: 0.00041805556 | Y3: 0.00041030093 | Z3: 0.00040763889 | AB3: 50m Retten | AC3: 0.2 | AD3: 0.2 | AE3: 0.2 | AF3: 0 | AG3: 0 | AH3: 0.16 | AI3: 0.16 | AJ3: 0.16 | AK3: 0 | AL3: 0 | AM3: 0 | AN3: 0 | AO3: 0.18 | AP3: 0.18 | AQ3: 0.18 | AR3: 0 | AS3: 0 | AT3: 0.17 | AU3: 0.17 | AV3: 0.17 | AW3: 0 | AX3: 0 | AY3: 0 | AZ3: 0 | BB3: 50m Retten | BC3: =IF(AC3=0,"",C3+C3*AC3) -> 0.00044861111 | BD3: =IF(AD3=0,"",D3+D3*AD3) -> 0.00044430556 | BE3: =IF(AE3=0,"",E3+E3*AE3) -> 0.00043944444 | BF3: =IF(AF3=0,"",F3+F3*AF3) | BG3: =IF(AG3=0,"",G3+G3*AG3) | BH3: =IF(AH3=0,"",H3+H3*AH3) -> 0.00041888889 | BI3: =IF(AI3=0,"",I3+I3*AI3) -> 0.00041512963 | BJ3: =IF(AJ3=0,"",J3+J3*AJ3) -> 0.00040371759 | ... BZ3: =IF(AZ3=0,"",Z3+Z3*AZ3)
